fixtures/events.jsonl
{"stream":"bidask","exchange":"TSE","security_type":"STK","symbol":"2330","event_ts":"2026-01-02T09:00:00.100000+08:00","received_ts":"2026-01-02T09:00:00.105000+08:00","bid_price":[100.0,99.5,99.0,98.5,98.0],"bid_volume":[10,20,30,40,50],"ask_price":[100.5,101.0,101.5,102.0,102.5],"ask_volume":[11,21,31,41,51],"diff_bid_vol":[1,2,3,4,5],"diff_ask_vol":[-1,-2,-3,-4,-5],"simtrade":true,"intraday_odd":false}
{"stream":"tick","exchange":"TSE","security_type":"STK","symbol":"2330","event_ts":"2026-01-02T09:00:00.200000+08:00","received_ts":"2026-01-02T09:00:00.207000+08:00","close":100.5,"volume":2,"total_volume":2,"tick_type":1,"best_bid_price":100.0,"best_bid_volume":10,"best_ask_price":100.5,"best_ask_volume":11,"simtrade":true,"intraday_odd":false}
